<?xml version="1.0"?>
<robot xmlns:xacro="http://www.ros.org/wiki/xacro">

    <material name="white">
        <color rgba="1 1 1 1"/>
    </material>

    <material name="blue">
        <color rgba="0 0 1 1"/>
    </material>

    <material name="red">
        <color rgba="1 0 0 1"/>
    </material>

    <material name="cyan">
        <color rgba="0 1 1 1"/>
    </material>

    <xacro:macro name="microServo" params="parent child origin axis">
        <joint name="${parent}_${child}_servo" type="revolute">
            <origin xyz="${origin}"/>
            <parent link="${parent}"/>
            <child link="${child}"/>
            <!-- axis of rotation, normalized -->
            <axis xyz="${axis}"/>
            <!-- limits of rotation (in radians) and movement -->
            <!-- TODO it might be nice to figure out how to 'macro' pi
            something like "${pi}" is possible but this is just a 
            simple test for now... -->
            <limit lower="-1.570796" upper="1.570796" effort="100" velocity="100"/>
        </joint>

        <!--
        <transmission name="${parent}-${child}-servo-trans">
            <type>transmission_interface/SimpleTransmission</type>
            <actuator name="${parent}-to-${child}">
              <mechanicalReduction>1</mechanicalReduction>
            </actuator>
            <joint name="${parent}-to-${child}-servo">
              <hardwareInterface>hardware_interface/PositionJointInterface</hardwareInterface>
            </joint>
        </transmission> -->
    </xacro:macro>

    <xacro:macro name="arm-segment" params="number origin x y z material">
        <link name="s${number}">
            <visual>
                <origin xyz="${origin}"/>
                <geometry> <box size="${x} ${y} ${z}"/> </geometry>
                <material name="${material}"/> 
            </visual>
            <collision>
                <origin xyz="${origin}"/>
                <geometry> <box size="${x} ${y} ${z}"/> </geometry>
            </collision>
            <xacro:inertial_box mass="1" x="${x}" y="${y}" z="${z}">
                <origin xyz="${origin}"/>
            </xacro:inertial_box>
        </link>
    </xacro:macro>


    <xacro:macro name="inertial_box" params="mass x y z *origin">
        <inertial>
            <xacro:insert_block name="origin"/>
            <mass value="${mass}" />
            <inertia ixx="${(1/12) * mass * (y*y+z*z)}" ixy="0.0" ixz="0.0"
                    iyy="${(1/12) * mass * (x*x+z*z)}" iyz="0.0"
                    izz="${(1/12) * mass * (x*x+y*y)}" />
        </inertial>
    </xacro:macro>


    <xacro:macro name="inertial_cylinder" params="mass length radius *origin">
        <inertial>
            <xacro:insert_block name="origin"/>
            <mass value="${mass}" />
            <inertia ixx="${(1/12) * mass * (3*radius*radius + length*length)}" ixy="0.0" ixz="0.0"
                    iyy="${(1/12) * mass * (3*radius*radius + length*length)}" iyz="0.0"
                    izz="${(1/2) * mass * (radius*radius)}" />
        </inertial>
    </xacro:macro>



</robot>
